<robot
  name="pz_car">
  <link
    name="base_link">
    <inertial>
      <origin
        xyz="0.0035404 -0.0077171 0.0022805"
        rpy="0 0 0" />
      <mass
        value="3.2454" />
      <inertia
        ixx="0.0049715"
        ixy="1.4899E-07"
        ixz="-7.702E-06"
        iyy="0.0067228"
        iyz="4.728E-08"
        izz="0.010337" />
    </inertial>
  </link>
  <link
    name="lf_wheel_link">
    <inertial>
      <origin
        xyz="-0.00025671 -0.018975 -3.4322E-05"
        rpy="0 0 0" />
      <mass
        value="0.0034889" />
      <inertia
        ixx="1.1787E-06"
        ixy="-3.6445E-21"
        ixz="-3.9071E-24"
        iyy="5.6412E-08"
        iyz="-1.807E-21"
        izz="1.1787E-06" />
    </inertial>
  </link>
  <joint
    name="joint_lf_wheel"
    type="continuous">
    <origin
      xyz="0.18316 0.1935 -0.06693"
      rpy="0 0 0" />
    <parent
      link="base_link" />
    <child
      link="lf_wheel_link" />
    <axis
      xyz="0 -1 0" />
  </joint>
  <link
    name="rf_wheel_link">
    <inertial>
      <origin
        xyz="-2.2071E-06 0.020501 -4.5906E-05"
        rpy="0 0 0" />
      <mass
        value="0.0010054" />
      <inertia
        ixx="1.6923E-08"
        ixy="-6.3149E-15"
        ixz="5.1733E-15"
        iyy="1.709E-08"
        iyz="9.9633E-15"
        izz="1.6923E-08" />
    </inertial>
  </link>
  <joint
    name="joint_rf_wheel"
    type="continuous">
    <origin
      xyz="0.18316 -0.1935 -0.06693"
      rpy="0 0 0" />
    <parent
      link="base_link" />
    <child
      link="rf_wheel_link" />
    <axis
      xyz="0 1 0" />
  </joint>
  <link
    name="lb_wheel_link">
    <inertial>
      <origin
        xyz="-2.3023E-05 -0.020501 0.0001283"
        rpy="0 0 0" />
      <mass
        value="0.0010053" />
      <inertia
        ixx="1.6923E-08"
        ixy="-6.3412E-15"
        ixz="-6.0987E-15"
        iyy="1.709E-08"
        iyz="-1.2778E-14"
        izz="1.6923E-08" />
    </inertial>
  </link>
  <joint
    name="joint_lb_wheel"
    type="continuous">
    <origin
      xyz="-0.17934 0.1935 -0.077849"
      rpy="0 0 0" />
    <parent
      link="base_link" />
    <child
      link="lb_wheel_link" />
    <axis
      xyz="0 1 0" />
  </joint>
  <link
    name="rb_wheel_link">
    <inertial>
      <origin
        xyz="0.00025671 0.018975 -3.4322E-05"
        rpy="0 0 0" />
      <mass
        value="0.0034889" />
      <inertia
        ixx="1.1787E-06"
        ixy="1.145E-21"
        ixz="-1.6698E-24"
        iyy="5.6412E-08"
        iyz="-5.6268E-21"
        izz="1.1787E-06" />
    </inertial>
    <robot
    name="pz_car">
    <link
      name="base_link">
      <inertial>
        <origin
          xyz="0.0035404 -0.0077171 0.0022805"
          rpy="0 0 0" />
        <mass
          value="3.2454" />
        <inertia
          ixx="0.0049715"
          ixy="1.4899E-07"
          ixz="-7.702E-06"
          iyy="0.0067228"
          iyz="4.728E-08"
          izz="0.010337" />
      </inertial>
    </link>
    <link
      name="lf_wheel_link">
      <inertial>
        <origin
          xyz="-0.00025671 -0.018975 -3.4322E-05"
          rpy="0 0 0" />
        <mass
          value="0.0034889" />
        <inertia
          ixx="1.1787E-06"
          ixy="-3.6445E-21"
          ixz="-3.9071E-24"
          iyy="5.6412E-08"
          iyz="-1.807E-21"
          izz="1.1787E-06" />
      </inertial>
    </link>
    <joint
      name="joint_lf_wheel"
      type="continuous">
      <origin
        xyz="0.18316 0.1935 -0.06693"
        rpy="0 0 0" />
      <parent
        link="base_link" />
      <child
        link="lf_wheel_link" />
      <axis
        xyz="0 -1 0" />
    </joint>
    <link
      name="rf_wheel_link">
      <inertial>
        <origin
          xyz="-2.2071E-06 0.020501 -4.5906E-05"
          rpy="0 0 0" />
        <mass
          value="0.0010054" />
        <inertia
          ixx="1.6923E-08"
          ixy="-6.3149E-15"
          ixz="5.1733E-15"
          iyy="1.709E-08"
          iyz="9.9633E-15"
          izz="1.6923E-08" />
      </inertial>
    </link>
    <joint
      name="joint_rf_wheel"
      type="continuous">
      <origin
        xyz="0.18316 -0.1935 -0.06693"
        rpy="0 0 0" />
      <parent
        link="base_link" />
      <child
        link="rf_wheel_link" />
      <axis
        xyz="0 1 0" />
    </joint>
    <link
      name="lb_wheel_link">
      <inertial>
        <origin
          xyz="-2.3023E-05 -0.020501 0.0001283"
          rpy="0 0 0" />
        <mass
          value="0.0010053" />
        <inertia
          ixx="1.6923E-08"
          ixy="-6.3412E-15"
          ixz="-6.0987E-15"
          iyy="1.709E-08"
          iyz="-1.2778E-14"
          izz="1.6923E-08" />
      </inertial>
      <visual>
        <origin
          xyz="0 0 0"
          rpy="0 0 0" />
        <geometry>
          <mesh
            filename="package://meshes/lb_wheel_link.STL" />
        </geometry>
        <material
          name="">
          <color
            rgba="0.22353 0.22353 0.22353 1" />
        </material>
      </visual>
      <collision>
        <origin
          xyz="0 0 0"
          rpy="0 0 0" />
        <geometry>
          <mesh
            filename="package://meshes/lb_wheel_link.STL" />
        </geometry>
      </collision>
    </link>
    <joint
      name="joint_lb_wheel"
      type="continuous">
      <origin
        xyz="-0.17934 0.1935 -0.077849"
        rpy="0 0 0" />
      <parent
        link="base_link" />
      <child
        link="lb_wheel_link" />
      <axis
        xyz="0 1 0" />
    </joint>
    <link
      name="rb_wheel_link">
      <inertial>
        <origin
          xyz="0.00025671 0.018975 -3.4322E-05"
          rpy="0 0 0" />
        <mass
          value="0.0034889" />
        <inertia
          ixx="1.1787E-06"
          ixy="1.145E-21"
          ixz="-1.6698E-24"
          iyy="5.6412E-08"
          iyz="-5.6268E-21"
          izz="1.1787E-06" />
      </inertial>
      <visual>
        <origin
          xyz="0 0 0"
          rpy="0 0 0" />
        <geometry>
          <mesh
            filename="package://meshes/rb_wheel_link.STL" />
        </geometry>
        <material
          name="">
          <color
            rgba="0.22353 0.22353 0.22353 1" />
        </material>
      </visual>
      <collision>
        <origin
          xyz="0 0 0"
          rpy="0 0 0" />
        <geometry>
          <mesh
            filename="package://meshes/rb_wheel_link.STL" />
        </geometry>
      </collision>
    </link>
    <joint
      name="joint_rb_wheel"
      type="continuous">
      <origin
        xyz="-0.17865 -0.1935 -0.077434"
        rpy="0 0 0" />
      <parent
        link="base_link" />
      <child
        link="rb_wheel_link" />
      <axis
        xyz="0 1 0" />
    </joint>
    <link
      name="laser_link">
      <inertial>
        <origin
          xyz="0 0 0"
          rpy="0 0 0" />
        <mass
          value="0" />
        <inertia
          ixx="0"
          ixy="0"
          ixz="0"
          iyy="0"
          iyz="0"
          izz="0" />
      </inertial>
      <visual>
        <origin
          xyz="0 0 0"
          rpy="0 0 0" />
        <geometry>
          <mesh
            filename="package://meshes/laser_link.STL" />
        </geometry>
        <material
          name="">
          <color
            rgba="1 1 1 1" />
        </material>
      </visual>
      <collision>
        <origin
          xyz="0 0 0"
          rpy="0 0 0" />
        <geometry>
          <mesh
            filename="package://meshes/laser_link.STL" />
        </geometry>
      </collision>
    </link>
    <joint
      name="joint_laser"
      type="fixed">
      <origin
        xyz="0.13 0 0.104"
        rpy="0 0 0" />
      <parent
        link="base_link" />
      <child
        link="laser_link" />
      <axis
        xyz="0 0 0" />
    </joint>
  </robot>  </link>
  <joint
    name="joint_rb_wheel"
    type="continuous">
    <origin
      xyz="-0.17865 -0.1935 -0.077434"
      rpy="0 0 0" />
    <parent
      link="base_link" />
    <child
      link="rb_wheel_link" />
    <axis
      xyz="0 1 0" />
  </joint>
  <link
    name="laser_link">
    <inertial>
      <origin
        xyz="0 0 0"
        rpy="0 0 0" />
      <mass
        value="0" />
      <inertia
        ixx="0"
        ixy="0"
        ixz="0"
        iyy="0"
        iyz="0"
        izz="0" />
    </inertial>
  </link>
  <joint
    name="joint_laser"
    type="fixed">
    <origin
      xyz="0.13 0 0.104"
      rpy="0 0 0" />
    <parent
      link="base_link" />
    <child
      link="laser_link" />
    <axis
      xyz="0 0 0" />
  </joint>
</robot>